Workbook

Sheet Summary
A1: FIN·OS phone app — parity with the website
A2: Source of truth: the 'Parity Tracker' sheet. Counts below are formulas. Last built 2026-10-12.
A4: Area | B4: Done | C4: Partial | D4: Pending | E4: Blocked | F4: Not planned | G4: Total | H4: % done (of planned)
A5: Trackers & planners | B5: =COUNTIFS('Parity Tracker'!$B$2:$B$255,$A5,'Parity Tracker'!$E$2:$E$255,"Done") -> 27 | C5: =COUNTIFS('Parity Tracker'!$B$2:$B$255,$A5,'Parity Tracker'!$E$2:$E$255,"Partial") -> 3 | D5: =COUNTIFS('Parity Tracker'!$B$2:$B$255,$A5,'Parity Tracker'!$E$2:$E$255,"Pending") -> 9 | E5: =COUNTIFS('Parity Tracker'!$B$2:$B$255,$A5,'Parity Tracker'!$E$2:$E$255,"Blocked") -> 0 | F5: =COUNTIFS('Parity Tracker'!$B$2:$B$255,$A5,'Parity Tracker'!$E$2:$E$255,"Not planned") -> 1 | G5: =SUM(B5:F5) -> 40 | H5: =IF((G5-F5)=0,0,(B5+0.5*C5)/(G5-F5)) -> 0.73076923
A6: Calculators | B6: =COUNTIFS('Parity Tracker'!$B$2:$B$255,$A6,'Parity Tracker'!$E$2:$E$255,"Done") -> 2 | C6: =COUNTIFS('Parity Tracker'!$B$2:$B$255,$A6,'Parity Tracker'!$E$2:$E$255,"Partial") -> 0 | D6: =COUNTIFS('Parity Tracker'!$B$2:$B$255,$A6,'Parity Tracker'!$E$2:$E$255,"Pending") -> 88 | E6: =COUNTIFS('Parity Tracker'!$B$2:$B$255,$A6,'Parity Tracker'!$E$2:$E$255,"Blocked") -> 0 | F6: =COUNTIFS('Parity Tracker'!$B$2:$B$255,$A6,'Parity Tracker'!$E$2:$E$255,"Not planned") -> 0 | G6: =SUM(B6:F6) -> 90 | H6: =IF((G6-F6)=0,0,(B6+0.5*C6)/(G6-F6)) -> 0.022222222
A7: Learning & education | B7: =COUNTIFS('Parity Tracker'!$B$2:$B$255,$A7,'Parity Tracker'!$E$2:$E$255,"Done") -> 0 | C7: =COUNTIFS('Parity Tracker'!$B$2:$B$255,$A7,'Parity Tracker'!$E$2:$E$255,"Partial") -> 0 | D7: =COUNTIFS('Parity Tracker'!$B$2:$B$255,$A7,'Parity Tracker'!$E$2:$E$255,"Pending") -> 51 | E7: =COUNTIFS('Parity Tracker'!$B$2:$B$255,$A7,'Parity Tracker'!$E$2:$E$255,"Blocked") -> 0 | F7: =COUNTIFS('Parity Tracker'!$B$2:$B$255,$A7,'Parity Tracker'!$E$2:$E$255,"Not planned") -> 0 | G7: =SUM(B7:F7) -> 51 | H7: =IF((G7-F7)=0,0,(B7+0.5*C7)/(G7-F7)) -> 0
A8: Markets & research | B8: =COUNTIFS('Parity Tracker'!$B$2:$B$255,$A8,'Parity Tracker'!$E$2:$E$255,"Done") -> 2 | C8: =COUNTIFS('Parity Tracker'!$B$2:$B$255,$A8,'Parity Tracker'!$E$2:$E$255,"Partial") -> 0 | D8: =COUNTIFS('Parity Tracker'!$B$2:$B$255,$A8,'Parity Tracker'!$E$2:$E$255,"Pending") -> 18 | E8: =COUNTIFS('Parity Tracker'!$B$2:$B$255,$A8,'Parity Tracker'!$E$2:$E$255,"Blocked") -> 1 | F8: =COUNTIFS('Parity Tracker'!$B$2:$B$255,$A8,'Parity Tracker'!$E$2:$E$255,"Not planned") -> 0 | G8: =SUM(B8:F8) -> 21 | H8: =IF((G8-F8)=0,0,(B8+0.5*C8)/(G8-F8)) -> 0.095238095
A9: Portfolio & standalone apps | B9: =COUNTIFS('Parity Tracker'!$B$2:$B$255,$A9,'Parity Tracker'!$E$2:$E$255,"Done") -> 2 | C9: =COUNTIFS('Parity Tracker'!$B$2:$B$255,$A9,'Parity Tracker'!$E$2:$E$255,"Partial") -> 0 | D9: =COUNTIFS('Parity Tracker'!$B$2:$B$255,$A9,'Parity Tracker'!$E$2:$E$255,"Pending") -> 7 | E9: =COUNTIFS('Parity Tracker'!$B$2:$B$255,$A9,'Parity Tracker'!$E$2:$E$255,"Blocked") -> 0 | F9: =COUNTIFS('Parity Tracker'!$B$2:$B$255,$A9,'Parity Tracker'!$E$2:$E$255,"Not planned") -> 1 | G9: =SUM(B9:F9) -> 10 | H9: =IF((G9-F9)=0,0,(B9+0.5*C9)/(G9-F9)) -> 0.22222222
A10: Arya AI | B10: =COUNTIFS('Parity Tracker'!$B$2:$B$255,$A10,'Parity Tracker'!$E$2:$E$255,"Done") -> 2 | C10: =COUNTIFS('Parity Tracker'!$B$2:$B$255,$A10,'Parity Tracker'!$E$2:$E$255,"Partial") -> 0 | D10: =COUNTIFS('Parity Tracker'!$B$2:$B$255,$A10,'Parity Tracker'!$E$2:$E$255,"Pending") -> 7 | E10: =COUNTIFS('Parity Tracker'!$B$2:$B$255,$A10,'Parity Tracker'!$E$2:$E$255,"Blocked") -> 0 | F10: =COUNTIFS('Parity Tracker'!$B$2:$B$255,$A10,'Parity Tracker'!$E$2:$E$255,"Not planned") -> 0 | G10: =SUM(B10:F10) -> 9 | H10: =IF((G10-F10)=0,0,(B10+0.5*C10)/(G10-F10)) -> 0.22222222
A11: Platform & account | B11: =COUNTIFS('Parity Tracker'!$B$2:$B$255,$A11,'Parity Tracker'!$E$2:$E$255,"Done") -> 5 | C11: =COUNTIFS('Parity Tracker'!$B$2:$B$255,$A11,'Parity Tracker'!$E$2:$E$255,"Partial") -> 0 | D11: =COUNTIFS('Parity Tracker'!$B$2:$B$255,$A11,'Parity Tracker'!$E$2:$E$255,"Pending") -> 11 | E11: =COUNTIFS('Parity Tracker'!$B$2:$B$255,$A11,'Parity Tracker'!$E$2:$E$255,"Blocked") -> 0 | F11: =COUNTIFS('Parity Tracker'!$B$2:$B$255,$A11,'Parity Tracker'!$E$2:$E$255,"Not planned") -> 0 | G11: =SUM(B11:F11) -> 16 | H11: =IF((G11-F11)=0,0,(B11+0.5*C11)/(G11-F11)) -> 0.3125
A12: Release readiness | B12: =COUNTIFS('Parity Tracker'!$B$2:$B$255,$A12,'Parity Tracker'!$E$2:$E$255,"Done") -> 3 | C12: =COUNTIFS('Parity Tracker'!$B$2:$B$255,$A12,'Parity Tracker'!$E$2:$E$255,"Partial") -> 2 | D12: =COUNTIFS('Parity Tracker'!$B$2:$B$255,$A12,'Parity Tracker'!$E$2:$E$255,"Pending") -> 6 | E12: =COUNTIFS('Parity Tracker'!$B$2:$B$255,$A12,'Parity Tracker'!$E$2:$E$255,"Blocked") -> 6 | F12: =COUNTIFS('Parity Tracker'!$B$2:$B$255,$A12,'Parity Tracker'!$E$2:$E$255,"Not planned") -> 0 | G12: =SUM(B12:F12) -> 17 | H12: =IF((G12-F12)=0,0,(B12+0.5*C12)/(G12-F12)) -> 0.23529412
A13: All areas | B13: =SUM(B5:B12) -> 43 | C13: =SUM(C5:C12) -> 5 | D13: =SUM(D5:D12) -> 197 | E13: =SUM(E5:E12) -> 7 | F13: =SUM(F5:F12) -> 2 | G13: =SUM(G5:G12) -> 254 | H13: =IF((G13-F13)=0,0,(B13+0.5*C13)/(G13-F13)) -> 0.18055556
A15: Open work by priority
A16: Priority | B16: Not done yet (Partial + Pending + Blocked) | C16: Meaning
A17: P0 | B17: =COUNTIFS('Parity Tracker'!$F$2:$F$255,$A17,'Parity Tracker'!$E$2:$E$255,"Partial")+COUNTIFS('Parity Tracker'!$F$2:$F$255,$A17,'Parity Tracker'!$E$2:$E$255,"Pending")+COUNTIFS('Parity Tracker'!$F$2:$F$255,$A17,'Parity Tracker'!$E$2:$E$255,"Blocked") -> 8 | C17: Release blockers — cannot ship without these
A18: P1 | B18: =COUNTIFS('Parity Tracker'!$F$2:$F$255,$A18,'Parity Tracker'!$E$2:$E$255,"Partial")+COUNTIFS('Parity Tracker'!$F$2:$F$255,$A18,'Parity Tracker'!$E$2:$E$255,"Pending")+COUNTIFS('Parity Tracker'!$F$2:$F$255,$A18,'Parity Tracker'!$E$2:$E$255,"Blocked") -> 5 | C18: High value for daily use
A19: P2 | B19: =COUNTIFS('Parity Tracker'!$F$2:$F$255,$A19,'Parity Tracker'!$E$2:$E$255,"Partial")+COUNTIFS('Parity Tracker'!$F$2:$F$255,$A19,'Parity Tracker'!$E$2:$E$255,"Pending")+COUNTIFS('Parity Tracker'!$F$2:$F$255,$A19,'Parity Tracker'!$E$2:$E$255,"Blocked") -> 20 | C19: Useful, after P1
A20: P3 | B20: =COUNTIFS('Parity Tracker'!$F$2:$F$255,$A20,'Parity Tracker'!$E$2:$E$255,"Partial")+COUNTIFS('Parity Tracker'!$F$2:$F$255,$A20,'Parity Tracker'!$E$2:$E$255,"Pending")+COUNTIFS('Parity Tracker'!$F$2:$F$255,$A20,'Parity Tracker'!$E$2:$E$255,"Blocked") -> 176 | C20: Long tail / nice to have
A22: How to read '% done': Done counts 1, Partial counts 0.5, Not planned is left out of the denominator.
A23: Counts are of rows in the tracker, not of effort: one row can be a 30-minute port or a multi-day feature (see Effort).

Sheet Parity Tracker
A1: ID | B1: Area | C1: Feature | D1: Website source | E1: Phone status | F1: Priority | G1: Effort | H1: Build order | I1: Planned phone location | J1: Notes | K1: Updated
A2: T-01 | B2: Trackers & planners | C2: Portfolio Growth Simulator | D2: html/portfolio.html | E2: Pending | F2: P3 | G2: M | I2: tools/… | K2: 2026-10-12
A3: T-02 | B3: Trackers & planners | C3: Budget Forecast (pace, AI forecast) | D3: html/budget-forecast.html | E3: Partial | F3: P2 | G3: M | I3: tracker/budget | J3: Category limits, pace and suggestions are done; the forecast view is not | K3: 2026-10-12
A4: T-03 | B4: Trackers & planners | C4: Subscription Tracker | D4: html/subscription-tracker.html | E4: Done | F4: P2 | G4: M | I4: tracker/subscriptions | J4: Parity-tested against js/finos-subscriptions.js | K4: 2026-10-12
A5: T-04 | B5: Trackers & planners | C5: Credit Score Tracker | D5: html/credit-score.html | E5: Done | F5: P2 | G5: S | I5: tools/credit | J5: CIBIL band, home-loan rate impact, ranked improvement tips; nothing assumed when a figure was not typed; parity-tested vs js/finos-credit-score.js | K5: 2026-10-12
A6: T-05 | B6: Trackers & planners | C6: Crypto Tracker | D6: html/crypto-tracker.html | E6: Done | F6: P2 | G6: M | I6: tracker/crypto | J6: Holdings, P&L, 31.2% tax on each coin's gain, 1% TDS what-if; prices are typed (never fetched); parity-tested vs js/finos-crypto-tracker.js | K6: 2026-10-12
A7: T-06 | B7: Trackers & planners | C7: Debt Optimizer (avalanche / snowball) | D7: html/debt-optimizer.html | E7: Done | F7: P1 | G7: M | H7: 7 | I7: tools/debt | J7: Avalanche vs snowball + home-loan prepayment impact; shares balances with Net Worth; parity-tested vs js/finos-debt-optimizer.js | K7: 2026-10-12
A8: T-07 | B8: Trackers & planners | C8: Emergency Fund Tracker | D8: html/emergency-fund.html | E8: Done | F8: P2 | G8: S | I8: tracker/emergency | K8: 2026-10-12
A9: T-08 | B9: Trackers & planners | C9: EPF Tracker | D9: html/epf-tracker.html | E9: Done | F9: P2 | G9: M | I9: tracker/epf | K9: 2026-10-12
A10: T-09 | B10: Trackers & planners | C10: Fixed Income (FD) Tracker | D10: html/fd-tracker.html | E10: Done | F10: P1 | G10: M | H10: 9 | I10: tracker/fixed | J10: FD, RD, PPF, NSC, SCSS, Sukanya, bonds, post office; same finos_fd_portfolio key as the web; parity-tested; RD 0% division guarded | K10: 2026-10-12
A11: T-10 | B11: Trackers & planners | C11: Financial Calendar (+ reminders) | D11: html/financial-calendar.html | E11: Partial | F11: P1 | G11: L | H11: 11 | I11: tools/calendar | J11: Month grid, day detail, coming-up list, summary cards: SIP, deposit maturities (real terms), insurance, goals, subscriptions, tax dates; parity-tested. Phone notifications NOT built: need an OS notification permission, which the privacy guard test currently forbids (owner decision). | K11: 2026-10-12
A12: T-11 | B12: Trackers & planners | C12: Financial Command Hub | D12: html/financial-hub.html | E12: Not planned | F12: P3 | G12: S | J12: Dashboard + Track tab already do this job | K12: 2026-10-12
A13: T-12 | B13: Trackers & planners | C13: Goal Optimizer | D13: html/goal-optimizer.html | E13: Done | F13: P2 | G13: M | I13: tools/goalopt (from Goals) | J13: Inflation-adjusted SIP per goal, priority score, feasibility vs what you can invest, competing-goal conflicts; parity-tested vs js/finos-goal-optimizer.js. Website corrected in the same pass: saved money compounds as today's rupees (it was taken as a % of the inflated target, counting inflation twice). | K13: 2026-10-12
A14: T-13 | B14: Trackers & planners | C14: Gold Tracker | D14: html/gold-tracker.html | E14: Done | F14: P1 | G14: M | H14: 10 | I14: tracker/gold | J14: Physical, SGB, gold ETF, gold MF; user-typed price only (no invented rate); coupon; parity-tested vs js/finos-gold-tracker.js | K14: 2026-10-12
A15: T-14 | B15: Trackers & planners | C15: Home Loan EMI Planner | D15: html/home-loan.html | E15: Done | F15: P1 | G15: M | H15: 8 | I15: tools/homeloan | J15: EMI, amortisation, affordability, 24(b)/80C deductions, prepayment impact; parity-tested. Website's PMAY-CLSS 'eligible' banner deliberately not ported (scheme bands ended); writes loan keys only on 'Save as my home loan'. | K15: 2026-10-12
A16: T-15 | B16: Trackers & planners | C16: Insurance Hub (directory, compare) | D16: html/insurance-hub.html | E16: Partial | F16: P2 | G16: M | I16: tracker/insurance | J16: Policies, gaps and renewals are done; directory/compare is not | K16: 2026-10-12
A17: T-16 | B17: Trackers & planners | C17: ITR Filing Prep Kit | D17: html/itr-summary.html | E17: Done | F17: P2 | G17: M | I17: tools/itr (from Tax planner) | J17: Income, 80C itemised, 80CCD/80D/24(b)/80E/80TTA, both regimes, TDS and balance/refund; the calculation is sliced unchanged from js/finos-itr-summary.js and parity-tested; figures live under the website's keys. Capital gains and surcharge are not in this worksheet (the Tax Planner has them). | K17: 2026-10-12
A18: T-17 | B18: Trackers & planners | C18: Life Insurance Need Calculator | D18: html/life-cover.html | E18: Done | F18: P2 | G18: S | I18: tools/lifecover (from Insurance) | J18: Human life value + income replacement + debts − existing cover, status band, rough premium illustration; parity-tested vs js/finos-life-cover.js; prefilled from income, spending, policies and loans. | K18: 2026-10-12
A19: T-18 | B19: Trackers & planners | C19: Life Goals Planner | D19: html/life-goals-planner.html | E19: Pending | F19: P2 | G19: M | I19: tracker/goals | K19: 2026-10-12
A20: T-19 | B20: Trackers & planners | C20: Mutual Fund Intelligence | D20: html/mf-intelligence.html | E20: Pending | F20: P2 | G20: L | I20: markets/mf | K20: 2026-10-12
A21: T-20 | B21: Trackers & planners | C21: Net Worth Tracker | D21: html/net-worth.html | E21: Done | F21: P2 | G21: M | I21: tracker/networth | K21: 2026-10-12
A22: T-21 | B22: Trackers & planners | C22: NPS Tracker | D22: html/nps-tracker.html | E22: Done | F22: P2 | G22: M | I22: tracker/nps | K22: 2026-10-12
A23: T-22 | B23: Trackers & planners | C23: Passive Income Tracker | D23: html/passive-income.html | E23: Done | F23: P2 | G23: S | I23: tracker/passive | J23: Streams (dividend, FD, rental, SWP, SGB, other), coverage of monthly spending, freedom milestones, what-if, extra corpus at 4%; totals parity-tested vs js/finos-passive-income.js; FD/SGB seed lines are labelled as estimates. | K23: 2026-10-12
A24: T-23 | B24: Trackers & planners | C24: Portfolio Rebalancer | D24: html/portfolio-rebalancer.html | E24: Done | F24: P2 | G24: M | I24: tools/rebalance | J24: Six asset classes from the other trackers, target presets + editor, drift and action per class, new-money split; parity-tested vs js/finos-rebalancer.js. Differences: empty portfolio is not flagged, property and govt savings are advised as 'send new money elsewhere'. | K24: 2026-10-12
A25: T-24 | B25: Trackers & planners | C25: PPF & Small Savings Tracker | D25: html/ppf-tracker.html | E25: Done | F25: P2 | G25: M | I25: tracker/ppf | K25: 2026-10-12
A26: T-25 | B26: Trackers & planners | C26: Real Estate Intelligence | D26: html/real-estate.html | E26: Pending | F26: P3 | G26: M | I26: tools/real-estate | K26: 2026-10-12
A27: T-26 | B27: Trackers & planners | C27: Retirement Planner (Monte Carlo success odds) | D27: html/retirement-planner.html | E27: Done | F27: P1 | G27: L | H27: 3 | I27: tools/retirement | J27: Built: corpus by source, 25× need, gap, income, Monte Carlo odds, fan chart, SIP solver. Engine identical to js/finos-montecarlo.js (40 random configs) and plan arithmetic identical on 400 random profiles. | K27: 2026-10-12
A28: T-27 | B28: Trackers & planners | C28: Salary Optimizer (CTC restructure) | D28: html/salary-optimizer.html | E28: Done | F28: P1 | G28: M | H28: 5 | I28: tools/salary | J28: CTC breakup → gross, HRA three-way minimum, tax in both regimes, take-home, restructuring tips; parity-tested. Take-home becomes income only on tap (the website overwrites finos_monthly_income on every render). | K28: 2026-10-12
A29: T-28 | B29: Trackers & planners | C29: SIP Step-Up Planner | D29: html/sip-stepup.html | E29: Done | F29: P1 | G29: S | H29: 6 | I29: tools/stepup | J29: Flat vs stepped-up SIP, scenario cards (5/10/15/20%), corpus chart, year table, milestones; parity-tested vs js/finos-sip-stepup.js incl. out-of-range inputs | K29: 2026-10-12
A30: T-29 | B30: Trackers & planners | C30: Tax Loss / Gain Harvesting | D30: html/tax-harvest.html | E30: Pending | F30: P2 | G30: M | I30: tools/tax-harvest | J30: Needs holdings with purchase dates | K30: 2026-10-12
A31: T-30 | B31: Trackers & planners | C31: Bonus & Windfall Allocator | D31: html/windfall.html | E31: Done | F31: P2 | G31: S | I31: tools/windfall | J31: Same waterfall as js/finos-windfall.js (parity-tested on 1,000 households) plus bonus/RSU tax impact; unknown spending is flagged instead of silently assuming ₹50,000; property note updated to the July 2024 rules. | K31: 2026-10-12
A32: T-31 | B32: Trackers & planners | C32: Tax (regime compare, Tax Savings Tracker, Tax Planner) | D32: html/tax.html | E32: Done | F32: P1 | G32: L | H32: 4 | I32: tools/tax + tools/taxplanner | J32: Savings tracker (headroom per section) and the full Tax Planner (both regimes with surcharge, HRA, 80C/80D/NPS/24(b), LTCG/STCG, action list); parity-tested vs js/finos-tax-calc.js. Web surcharge fixed in the same pass (taxable income, new-regime top rate 25%). | K32: 2026-10-12
A33: T-32 | B33: Trackers & planners | C33: Money Score | D33: html/money-score.html | E33: Done | F33: P1 | G33: L | I33: tools/score | J33: Parity-tested against js/finos-money-score.js | K33: 2026-10-12
A34: T-33 | B34: Trackers & planners | C34: Future Loss / System Leak | D34: html/system-leak.html | E34: Done | F34: P1 | G34: M | H34: 12 | I34: tools/leak | J34: Monthly leak from the ledger + subscriptions, 10/20/30-year future value, redirect share; parity-tested vs js/finos-leak.js | K34: 2026-10-12
A35: T-34 | B35: Trackers & planners | C35: Import bank statement | D35: html/import-statement.html | E35: Done | F35: P1 | G35: M | I35: tracker/import | K35: 2026-10-12
A36: T-35 | B36: Trackers & planners | C36: Budget & transactions (track finances) | D36: html/track-finances.html | E36: Done | F36: P1 | G36: L | I36: tracker/budget + transactions | J36: Quick-log and recurring entries are phone-only extras | K36: 2026-10-12
A37: T-36 | B37: Trackers & planners | C37: Financial Health Score (7 pillars) | D37: js/finos-health-score.js | E37: Done | F37: P1 | G37: M | I37: tracker/health | K37: 2026-10-12
A38: T-37 | B38: Trackers & planners | C38: Financial Report | D38: html/financial-report.html | E38: Pending | F38: P3 | G38: M | I38: tools/report | K38: 2026-10-12
A39: T-38 | B39: Trackers & planners | C39: Couple Finance | D39: html/couple-finance.html | E39: Pending | F39: P3 | G39: L | I39: tools/couple | J39: Needs the couple_* Supabase tables | K39: 2026-10-12
A40: T-39 | B40: Trackers & planners | C40: Benchmarking (vs similar profiles) | D40: html/benchmarking.html | E40: Pending | F40: P3 | G40: M | I40: tools/benchmark | K40: 2026-10-12
...

Sheet Build order
A1: Order | B1: ID | C1: Feature | D1: Area | E1: Priority | F1: Effort | G1: Phone status | H1: Notes
A2: 1 | B2: R-01 | C2: =INDEX('Parity Tracker'!$C$2:$C$255,MATCH($B2,'Parity Tracker'!$A$2:$A$255,0)) -> Run supabase/profiles_rls.sql (closes the open profiles table) | D2: =INDEX('Parity Tracker'!$B$2:$B$255,MATCH($B2,'Parity Tracker'!$A$2:$A$255,0)) -> Release readiness | E2: =INDEX('Parity Tracker'!$F$2:$F$255,MATCH($B2,'Parity Tracker'!$A$2:$A$255,0)) -> P0 | F2: =INDEX('Parity Tracker'!$G$2:$G$255,MATCH($B2,'Parity Tracker'!$A$2:$A$255,0)) -> S | G2: =INDEX('Parity Tracker'!$E$2:$E$255,MATCH($B2,'Parity Tracker'!$A$2:$A$255,0)) -> Blocked | H2: =INDEX('Parity Tracker'!$J$2:$J$255,MATCH($B2,'Parity Tracker'!$A$2:$A$255,0)) -> Needs the user's Supabase dashboard login — 13 profile rows were readable with the public key
A3: 1 | B3: R-02 | C3: =INDEX('Parity Tracker'!$C$2:$C$255,MATCH($B3,'Parity Tracker'!$A$2:$A$255,0)) -> Run core_tables.sql, holdings.sql, tracker_snapshot.sql | D3: =INDEX('Parity Tracker'!$B$2:$B$255,MATCH($B3,'Parity Tracker'!$A$2:$A$255,0)) -> Release readiness | E3: =INDEX('Parity Tracker'!$F$2:$F$255,MATCH($B3,'Parity Tracker'!$A$2:$A$255,0)) -> P0 | F3: =INDEX('Parity Tracker'!$G$2:$G$255,MATCH($B3,'Parity Tracker'!$A$2:$A$255,0)) -> S | G3: =INDEX('Parity Tracker'!$E$2:$E$255,MATCH($B3,'Parity Tracker'!$A$2:$A$255,0)) -> Blocked | H3: =INDEX('Parity Tracker'!$J$2:$J$255,MATCH($B3,'Parity Tracker'!$A$2:$A$255,0)) -> Needs the user's Supabase dashboard login
A4: 1 | B4: R-03 | C4: =INDEX('Parity Tracker'!$C$2:$C$255,MATCH($B4,'Parity Tracker'!$A$2:$A$255,0)) -> Real sign-in + sync test on the live project | D4: =INDEX('Parity Tracker'!$B$2:$B$255,MATCH($B4,'Parity Tracker'!$A$2:$A$255,0)) -> Release readiness | E4: =INDEX('Parity Tracker'!$F$2:$F$255,MATCH($B4,'Parity Tracker'!$A$2:$A$255,0)) -> P0 | F4: =INDEX('Parity Tracker'!$G$2:$G$255,MATCH($B4,'Parity Tracker'!$A$2:$A$255,0)) -> S | G4: =INDEX('Parity Tracker'!$E$2:$E$255,MATCH($B4,'Parity Tracker'!$A$2:$A$255,0)) -> Blocked | H4: =INDEX('Parity Tracker'!$J$2:$J$255,MATCH($B4,'Parity Tracker'!$A$2:$A$255,0)) -> Needs the SQL above and the user's credentials
A5: 1 | B5: R-07 | C5: =INDEX('Parity Tracker'!$C$2:$C$255,MATCH($B5,'Parity Tracker'!$A$2:$A$255,0)) -> Restart Arya backend (new key + sector route) | D5: =INDEX('Parity Tracker'!$B$2:$B$255,MATCH($B5,'Parity Tracker'!$A$2:$A$255,0)) -> Release readiness | E5: =INDEX('Parity Tracker'!$F$2:$F$255,MATCH($B5,'Parity Tracker'!$A$2:$A$255,0)) -> P0 | F5: =INDEX('Parity Tracker'!$G$2:$G$255,MATCH($B5,'Parity Tracker'!$A$2:$A$255,0)) -> S | G5: =INDEX('Parity Tracker'!$E$2:$E$255,MATCH($B5,'Parity Tracker'!$A$2:$A$255,0)) -> Blocked | H5: =INDEX('Parity Tracker'!$J$2:$J$255,MATCH($B5,'Parity Tracker'!$A$2:$A$255,0)) -> Old process is still running without the new code
A6: 2 | B6: R-04 | C6: =INDEX('Parity Tracker'!$C$2:$C$255,MATCH($B6,'Parity Tracker'!$A$2:$A$255,0)) -> Privacy & consent screen (what is stored, what is shared, switches) | D6: =INDEX('Parity Tracker'!$B$2:$B$255,MATCH($B6,'Parity Tracker'!$A$2:$A$255,0)) -> Release readiness | E6: =INDEX('Parity Tracker'!$F$2:$F$255,MATCH($B6,'Parity Tracker'!$A$2:$A$255,0)) -> P0 | F6: =INDEX('Parity Tracker'!$G$2:$G$255,MATCH($B6,'Parity Tracker'!$A$2:$A$255,0)) -> M | G6: =INDEX('Parity Tracker'!$E$2:$E$255,MATCH($B6,'Parity Tracker'!$A$2:$A$255,0)) -> Done | H6: =INDEX('Parity Tracker'!$J$2:$J$255,MATCH($B6,'Parity Tracker'!$A$2:$A$255,0)) -> Built: what is on the phone (live counts), every data flow, never-do list, permissions, export / erase. Guard tests fail if a new host or permission appears. Operator details left blank on purpose.
A7: 2 | B7: R-05 | C7: =INDEX('Parity Tracker'!$C$2:$C$255,MATCH($B7,'Parity Tracker'!$A$2:$A$255,0)) -> Terms of use screen | D7: =INDEX('Parity Tracker'!$B$2:$B$255,MATCH($B7,'Parity Tracker'!$A$2:$A$255,0)) -> Release readiness | E7: =INDEX('Parity Tracker'!$F$2:$F$255,MATCH($B7,'Parity Tracker'!$A$2:$A$255,0)) -> P0 | F7: =INDEX('Parity Tracker'!$G$2:$G$255,MATCH($B7,'Parity Tracker'!$A$2:$A$255,0)) -> S | G7: =INDEX('Parity Tracker'!$E$2:$E$255,MATCH($B7,'Parity Tracker'!$A$2:$A$255,0)) -> Done | H7: =INDEX('Parity Tracker'!$J$2:$J$255,MATCH($B7,'Parity Tracker'!$A$2:$A$255,0)) -> Port of html/terms.html, kept as a draft for legal review; operator/liability/law not invented.
A8: 2 | B8: R-06 | C8: =INDEX('Parity Tracker'!$C$2:$C$255,MATCH($B8,'Parity Tracker'!$A$2:$A$255,0)) -> Account deletion + data erase | D8: =INDEX('Parity Tracker'!$B$2:$B$255,MATCH($B8,'Parity Tracker'!$A$2:$A$255,0)) -> Release readiness | E8: =INDEX('Parity Tracker'!$F$2:$F$255,MATCH($B8,'Parity Tracker'!$A$2:$A$255,0)) -> P0 | F8: =INDEX('Parity Tracker'!$G$2:$G$255,MATCH($B8,'Parity Tracker'!$A$2:$A$255,0)) -> M | G8: =INDEX('Parity Tracker'!$E$2:$E$255,MATCH($B8,'Parity Tracker'!$A$2:$A$255,0)) -> Partial | H8: =INDEX('Parity Tracker'!$J$2:$J$255,MATCH($B8,'Parity Tracker'!$A$2:$A$255,0)) -> App side built and tested (erase phone, delete cloud copy, delete account via RPC). Needs supabase/delete_account.sql run on the live project before 'Delete my account' works.
A9: 3 | B9: T-26 | C9: =INDEX('Parity Tracker'!$C$2:$C$255,MATCH($B9,'Parity Tracker'!$A$2:$A$255,0)) -> Retirement Planner (Monte Carlo success odds) | D9: =INDEX('Parity Tracker'!$B$2:$B$255,MATCH($B9,'Parity Tracker'!$A$2:$A$255,0)) -> Trackers & planners | E9: =INDEX('Parity Tracker'!$F$2:$F$255,MATCH($B9,'Parity Tracker'!$A$2:$A$255,0)) -> P1 | F9: =INDEX('Parity Tracker'!$G$2:$G$255,MATCH($B9,'Parity Tracker'!$A$2:$A$255,0)) -> L | G9: =INDEX('Parity Tracker'!$E$2:$E$255,MATCH($B9,'Parity Tracker'!$A$2:$A$255,0)) -> Done | H9: =INDEX('Parity Tracker'!$J$2:$J$255,MATCH($B9,'Parity Tracker'!$A$2:$A$255,0)) -> Built: corpus by source, 25× need, gap, income, Monte Carlo odds, fan chart, SIP solver. Engine identical to js/finos-montecarlo.js (40 random configs) and plan arithmetic identical on 400 random profiles.
A10: 4 | B10: T-31 | C10: =INDEX('Parity Tracker'!$C$2:$C$255,MATCH($B10,'Parity Tracker'!$A$2:$A$255,0)) -> Tax (regime compare, Tax Savings Tracker, Tax Planner) | D10: =INDEX('Parity Tracker'!$B$2:$B$255,MATCH($B10,'Parity Tracker'!$A$2:$A$255,0)) -> Trackers & planners | E10: =INDEX('Parity Tracker'!$F$2:$F$255,MATCH($B10,'Parity Tracker'!$A$2:$A$255,0)) -> P1 | F10: =INDEX('Parity Tracker'!$G$2:$G$255,MATCH($B10,'Parity Tracker'!$A$2:$A$255,0)) -> L | G10: =INDEX('Parity Tracker'!$E$2:$E$255,MATCH($B10,'Parity Tracker'!$A$2:$A$255,0)) -> Done | H10: =INDEX('Parity Tracker'!$J$2:$J$255,MATCH($B10,'Parity Tracker'!$A$2:$A$255,0)) -> Savings tracker (headroom per section) and the full Tax Planner (both regimes with surcharge, HRA, 80C/80D/NPS/24(b), LTCG/STCG, action list); parity-tested vs js/finos-tax-calc.js. Web surcharge fixed in the same pass (taxable income, new-regime top rate 25%).
A11: 5 | B11: T-27 | C11: =INDEX('Parity Tracker'!$C$2:$C$255,MATCH($B11,'Parity Tracker'!$A$2:$A$255,0)) -> Salary Optimizer (CTC restructure) | D11: =INDEX('Parity Tracker'!$B$2:$B$255,MATCH($B11,'Parity Tracker'!$A$2:$A$255,0)) -> Trackers & planners | E11: =INDEX('Parity Tracker'!$F$2:$F$255,MATCH($B11,'Parity Tracker'!$A$2:$A$255,0)) -> P1 | F11: =INDEX('Parity Tracker'!$G$2:$G$255,MATCH($B11,'Parity Tracker'!$A$2:$A$255,0)) -> M | G11: =INDEX('Parity Tracker'!$E$2:$E$255,MATCH($B11,'Parity Tracker'!$A$2:$A$255,0)) -> Done | H11: =INDEX('Parity Tracker'!$J$2:$J$255,MATCH($B11,'Parity Tracker'!$A$2:$A$255,0)) -> CTC breakup → gross, HRA three-way minimum, tax in both regimes, take-home, restructuring tips; parity-tested. Take-home becomes income only on tap (the website overwrites finos_monthly_income on every render).
A12: 6 | B12: T-28 | C12: =INDEX('Parity Tracker'!$C$2:$C$255,MATCH($B12,'Parity Tracker'!$A$2:$A$255,0)) -> SIP Step-Up Planner | D12: =INDEX('Parity Tracker'!$B$2:$B$255,MATCH($B12,'Parity Tracker'!$A$2:$A$255,0)) -> Trackers & planners | E12: =INDEX('Parity Tracker'!$F$2:$F$255,MATCH($B12,'Parity Tracker'!$A$2:$A$255,0)) -> P1 | F12: =INDEX('Parity Tracker'!$G$2:$G$255,MATCH($B12,'Parity Tracker'!$A$2:$A$255,0)) -> S | G12: =INDEX('Parity Tracker'!$E$2:$E$255,MATCH($B12,'Parity Tracker'!$A$2:$A$255,0)) -> Done | H12: =INDEX('Parity Tracker'!$J$2:$J$255,MATCH($B12,'Parity Tracker'!$A$2:$A$255,0)) -> Flat vs stepped-up SIP, scenario cards (5/10/15/20%), corpus chart, year table, milestones; parity-tested vs js/finos-sip-stepup.js incl. out-of-range inputs
A13: 7 | B13: T-06 | C13: =INDEX('Parity Tracker'!$C$2:$C$255,MATCH($B13,'Parity Tracker'!$A$2:$A$255,0)) -> Debt Optimizer (avalanche / snowball) | D13: =INDEX('Parity Tracker'!$B$2:$B$255,MATCH($B13,'Parity Tracker'!$A$2:$A$255,0)) -> Trackers & planners | E13: =INDEX('Parity Tracker'!$F$2:$F$255,MATCH($B13,'Parity Tracker'!$A$2:$A$255,0)) -> P1 | F13: =INDEX('Parity Tracker'!$G$2:$G$255,MATCH($B13,'Parity Tracker'!$A$2:$A$255,0)) -> M | G13: =INDEX('Parity Tracker'!$E$2:$E$255,MATCH($B13,'Parity Tracker'!$A$2:$A$255,0)) -> Done | H13: =INDEX('Parity Tracker'!$J$2:$J$255,MATCH($B13,'Parity Tracker'!$A$2:$A$255,0)) -> Avalanche vs snowball + home-loan prepayment impact; shares balances with Net Worth; parity-tested vs js/finos-debt-optimizer.js
... A20: 14 | B20: A-07 | C20: =INDEX('Parity Tracker'!$C$2:$C$255,MATCH($B20,'Parity Tracker'!$A$2:$A$255,0)) -> Arya: safety guardrails on advice prompts | D20: =INDEX('Parity Tracker'!$B$2:$B$255,MATCH($B20,'Parity Tracker'!$A$2:$A$255,0)) -> Arya AI | E20: =INDEX('Parity Tracker'!$F$2:$F$255,MATCH($B20,'Parity Tracker'!$A$2:$A$255,0)) -> P1 | F20: =INDEX('Parity Tracker'!$G$2:$G$255,MATCH($B20,'Parity Tracker'!$A$2:$A$255,0)) -> S | G20: =INDEX('Parity Tracker'!$E$2:$E$255,MATCH($B20,'Parity Tracker'!$A$2:$A$255,0)) -> Done | H20: =INDEX('Parity Tracker'!$J$2:$J$255,MATCH($B20,'Parity Tracker'!$A$2:$A$255,0)) -> Same rules and wording as js/arya-guardrails.js (parity-tested on 420+ pairs); tax-evasion requests are refused on the phone before any network call; notes are appended to finished or stopped answers.
A22: Order 1 items need the owner (Supabase dashboard / device credentials). The rest are built in sequence, top to bottom.

Sheet Build log
A1: Date | B1: ID(s) | C1: What was built | D1: Verification | E1: Tests after
A2: 2026-10-04 | B2: T-03, C-64, C-79 | C2: Subscription Tracker; Prepay-or-Invest; Job Offer Comparer | D2: Parity tests vs the website; preview run | E2: 22
A3: 2026-10-11 | B3: P-15, P-16 | C3: Tracker sync (three-way merge) + holdings sync; website sync upgraded to v2 | D3: Phone engine vs website module; PostgREST-rules server; mock-Supabase UI run | E3: 33
A4: 2026-10-11 | B4: M-01, M-02 | C4: Live sector indices; removed invented index prices, FII/DII and Account Aggregator demos | D4: Route verified in-process (8 sectors from NSE) | E4: 33
A5: 2026-10-12 | B5: T-34 | C5: Bank statement import (CSV / AA JSON): preview, dedupe, undo | D5: 700 random statements identical to the website; preview run | E5: 43
A6: 2026-10-12 | B6: T-32 | C6: Money Score: six pillars, ranked next moves, what-if, history | D6: 1,500 random inputs identical to the website; preview run | E6: 51
A7: 2026-10-12 | B7: R-04, R-05, R-06, R-17 | C7: Privacy & your data screen, Terms of use, export / erase / delete cloud copy / delete account (RPC); removed unused phone permissions | D7: 63 tests incl. guards (no new host, no new permission, no analytics SDK); preview run: counts, export without token, erase | E7: 63
A8: 2026-10-12 | B8: T-26 | C8: Retirement planner: projected corpus vs 25× need, Monte Carlo success odds (4,000 futures), fan chart, monthly-SIP solver | D8: Engine seeded-identical to the website on 40 configs; solveContribution identical (24,500 on the preview profile); plan identical on 400 random stored profiles | E8: 68
A9: 2026-10-12 | B9: T-31 (savings tracker), T-33, T-09, T-06 | C9: Tax Savings (deduction headroom vs regime), Future Loss, Deposits & fixed income, Debt payoff (avalanche / snowball) | D9: savingsPlan identical to the website on 2,000 random cases; leak on 800 ledgers; FD on 1,500 entries; debt on 600 loan sets; preview run of all four screens | E9: 94
A10: 2026-10-12 | B10: T-27, T-28, T-14 | C10: Salary structure (CTC → take-home, HRA, tips), SIP step-up planner, Home loan EMI & prepayment planner | D10: Salary 1,500 random salaries + tips identical to the website; step-up 1,500 inputs incl. junk; home loan 1,200 loans + prepayment; preview run of all three screens | E10: 127
A11: 2026-10-12 | B11: T-13, T-10 (calendar view) | C11: Gold tracker; Financial calendar (month grid, upcoming, summary) | D11: Gold total/coupon identical to the website on 400 portfolios; calendar events identical on 150 random households with a frozen clock; tax dates identical over 4 ranges; preview run | E11: 134
A12: 2026-10-12 | B12: S-02, A-07 | C12: Broker holdings CSV import (preview, replace-not-add, undo-safe); Arya safety guardrails | D12: Holdings parser identical to the website on 700 random files; guardrails identical on 405 user×reply pairs; preview run: import into Portfolio, evasion refused with no /api/chat request, normal answer streams | E12: 146
... A21: 2026-10-12 | B21: T-12 | C21: Goal optimizer (linked from Goals); website double-counted inflation on saved money and was fixed | D21: Identical to the corrected website on 800 random goal sets with a frozen clock; website suite 327/327; preview run | E21: 183

Sheet Legend
A1: Term | B1: Meaning
A2: Phone status | B2: Done = built, tested, verified in the preview. Partial = part of the website feature exists. Pending = not started. Blocked = needs something only the owner can provide. Not planned = deliberately left out.
A3: Priority | B3: P0 release blocker · P1 high value for daily use · P2 useful · P3 long tail
A4: Effort | B4: S = under a day · M = one to three days · L = more than three days (rough, for ordering only)
A5: Build order | B5: 1 = owner actions that unblock everything · 2 = store-required screens · 3 onward = the next ports, top to bottom
A6: Done means | B6: Pure logic ported with a parity test against the website's own module, storage covered by tests, and the screen exercised in the browser preview. Not yet run on a physical device.
A7: Editing | B7: Change 'Phone status' with the dropdown; the Summary and Build order sheets recalculate.
A8: Source | B8: Counts come from files on disk on 2026-10-12: 123 pages in html/, 90 calculators, 30 Command Hub entries in js/finos-search.js.
